Workbook

Sheet Change History
A1: CHANGE HISTORY
A2: Version No. | B2: Date | C2: Change Description | D2: Prepared By | E2: Reviewed By
A3: 1.1 | B3: 31.03.2013 | C3: Initial release | D3: Mohammed Sharqawy | E3: K.Hanumanth Rao
A4: 1.2 | B4: 04.11.2013 | C4: Addition of new risks & controls | D4: Anshuman Tripathi | E4: K.Hanumanth Rao
A5: 1.3 | B5: 09.02.2014 | C5: Addition of new risks & controls related to: | D5: Anshuman Tripathi | E5: K.Hanumanth Rao
C6: a) Unapproved Changes or Configurations in IT Applications
C7: b) Unapproved Changes or Configurations in IT Infrastructure
C8: c) ASRY Mail (Google Mail)
C9: d) Vendor Support
C10: e) Password List
C11: f) Databases
C12: g) Applications
C13: h) UNIX Server Operating Systems
C14: i) Windows Server Operating Systems
C15: j) Portable Data Storage Devices
C16: k) IT Policies & Procedures
C17: l) Loss of IT Assets
A18: 1.4 | B18: 11.05.2014 | C18: Additon of risks & controls related to: | D18: Anshuman Tripathi | E18: K.Hanumanth Rao
C19: a) End of Windows XP Support
C20: b) End of vendor support for Oracle database
A21: 1.5 | B21: 23.06.2014 | C21: Addition of new risks & controls related to: | D21: Anshuman Tripathi | E21: K.Hanumanth Rao
C22: a) Change Management
C23: b) Configuration Management
C24: c) Capacity Planning
C25: d) Application Development
C26: e) Project Management
C27: f) Mobile Computing
C28: g) Manage Engine
C29: h) Licenses
C30: i) Portable Wifi Devices
C31: Mapping of control numbers as per new ISO 27001:2013 standard
A32: 1.6 | B32: 02.12.2014 | C32: Addition of new risks & controls related to: | D32: Anshuman Tripathi | E32: K.Hanumanth Rao
C33: a) Oracle Financials
C34: b) Project Management
A35: 1.7 | B35: 28.04.2015 | C35: Addition of new risks & controls related to: | D35: Anshuman Tripathi | E35: K.Hanumanth Rao
C36: i) Laptop (Executive)
C37: ii) Laptop (Normal Users)
C38: iii) VMware Server
C39: iv) Exchange Server
C40: v) Anti Virus Server
...

Sheet Evaluation of Risk Exposure
B1: Evaluation of Risk Exposure – Guidelines (ASRY IT)
B3: Value | C3: Probability | F3: LEVEL
B4: 5 | C4: Almost CERTAIN to occur in most circumstances | F4: High
B5: 4 | C5: LIKELY to occur frequently | F5: High
B6: 3 | C6: POSSIBLE & likely to occur at some time | F6: Moderate
B7: 2 | C7: UNLIKELY to occur but could happen | F7: Low
B8: 1 | C8: May occur but only in RARE & exceptional circumstances | F8: Negligible
B12: Value | C12: Severity/Impact | F12: Level
B13: 5 | C13: Serious damage to financial condition, reputation or ability to meet business objectives | F13: Catastrophic
B14: 4 | C14: Would limit ability to meet business objectives | F14: Major
B15: 3 | C15: Marginal or localised impact on business objectives | F15: Moderate
B16: 2 | C16: No significant business impact | F16: Minor
B17: 1 | C17: Negligible Impact | F17: Insignificant

Sheet Risk Assessment Guidelines
A2: RISK ASSESSMENT GUIDE | C2: CONSEQUENCES
C3: Insignificant (1) | D3: Minor (2) | E3: Moderate (3) | F3: Major (4) | G3: Catastrophic (5)
A4: LIKELIHOOD | B4: Almost CERTAIN to occur in most circumstances (5) | C4: Low | D4: Moderate | E4: High | F4: High | G4: High
B5: LIKELY to occur frequently (4) | C5: Low | D5: Moderate | E5: High | F5: High | G5: High
B6: POSSIBLE & likely to occur at some time (3) | C6: Low | D6: Moderate | E6: Moderate | F6: High | G6: High
B7: UNLIKELY to occur but could happen (2) | C7: Low | D7: Low | E7: Moderate | F7: Moderate | G7: Moderate
B8: May occur but only in RARE & exceptional circumstances (1) | C8: Negligible | D8: Low | E8: Low | F8: Low | G8: Low
B11: Risk Rating Categorization
B12: High (Risk Score >750) | C12: Unacceptable Risk. Mitigation Required
B13: Moderate (Risk Score between 500-750) | C13: Acceptable only if no other method viable and with high level controls in place
B14: Low (Risk Score between 100-500) | C14: Acceptable with suitable controls
B15: Negligible (Risk Score <100) | C15: Acceptable with suitable controls

Sheet Asset Rating
A1: Asset Rating – Guidelines (ASRY IT)
B3: Low (1) | C3: Moderate (2) | D3: High (3) | E3: Critical (4)
A4: Confidentiality Preserving authorized restrictions on information access and disclosure, including means for protection of personal privacy and proprietary information | B4: The unauthorized disclosure of information could be expected to have a limited adverse effect on organizational operations, organizational assets, or individuals. | C4: The unauthorized disclosure of information could be expected to have a serious adverse effect on organizational operations, organizational assets, or individuals. | D4: The unauthorized disclosure of information could be expected to have a severe adverse effect on organizational operations, organizational assets, or individuals. | E4: The unauthorized disclosure of information could be expected to have a severe or catastrophic adverse effect on organizational operations, organizational assets, or individuals.
A5: Integrity Guarding against improper information modification or destruction, and includes ensuring information non-repudiation and authenticity. | B5: The modification or destruction of information could be expected to have a limited adverse effect on organizational operations, organizational assets, or individuals. | C5: The modification or destruction of information could be expected to have a serious adverse effect on organizational operations, organizational assets, or individuals. | D5: The modification or destruction of information could be expected to have a severe adverse effect on organizational operations, organizational assets, or individuals | E5: The modification or destruction of information could be expected to have a severe or catastrophic adverse effect on organizational operations, organizational assets, or individuals
A6: Availability Ensuring timely and reliable access to and use of information. | B6: The disruption of access to or use of information or an information system could be expected to have a limited adverse effect on organizational operations, organizational assets, or individuals. | C6: The disruption of access to or use of information or an information system could be expected to have a serious adverse effect on organizational operations, organizational assets, or individuals. | D6: The disruption of access to or use of information or an information system could be expected to have a severe adverse effect on organizational operations, organizational assets, or individuals | E6: The disruption of access to or use of information or an information system could be expected to have a severe or catastrophic adverse effect on organizational operations, organizational assets, or individuals

Sheet ASRY IT Risk Profiles
A1: ASRY IT Risk Profiles
C2: Risk Profile - Prior to Controls (2025) | M2: Risk Profile - After controls (2025)
A3: Probability | B3: 5 | C3: =COUNTIFS('IT Risk Assessment Sheet'!$M$2:$M$86, "5", 'IT Risk Assessment Sheet'!$N$2:$N$86, "1") -> 0 | D3: =COUNTIFS('IT Risk Assessment Sheet'!$M$2:$M$86, "5", 'IT Risk Assessment Sheet'!$N$2:$N$86, "2") -> 0 | E3: =COUNTIFS('IT Risk Assessment Sheet'!$M$2:$M$86, "5", 'IT Risk Assessment Sheet'!$N$2:$N$86, "3") -> 0 | F3: =COUNTIFS('IT Risk Assessment Sheet'!$M$2:$M$86, "5", 'IT Risk Assessment Sheet'!$N$2:$N$86, "4") -> 0 | G3: =COUNTIFS('IT Risk Assessment Sheet'!$M$2:$M$86, "5", 'IT Risk Assessment Sheet'!$N$2:$N$86, "5") -> 0 | K3: Probability | L3: 5 | M3: =COUNTIFS('IT Risk Assessment Sheet'!$R$2:$R$86, "5", 'IT Risk Assessment Sheet'!$S$2:$S$86, "1") -> 0 | N3: =COUNTIFS('IT Risk Assessment Sheet'!$R$2:$R$86, "5", 'IT Risk Assessment Sheet'!$S$2:$S$86, "2") -> 0 | O3: =COUNTIFS('IT Risk Assessment Sheet'!$R$2:$R$86, "5", 'IT Risk Assessment Sheet'!$S$2:$S$86, "3") -> 0 | P3: =COUNTIFS('IT Risk Assessment Sheet'!$R$2:$R$86, "5", 'IT Risk Assessment Sheet'!$S$2:$S$86, "4") -> 0 | Q3: =COUNTIFS('IT Risk Assessment Sheet'!$R$2:$R$86, "5", 'IT Risk Assessment Sheet'!$S$2:$S$86, "5") -> 0 | S3: Risk Legends
B4: 4 | C4: =COUNTIFS('IT Risk Assessment Sheet'!$M$2:$M$86, "4", 'IT Risk Assessment Sheet'!$N$2:$N$86, "1") -> 0 | D4: =COUNTIFS('IT Risk Assessment Sheet'!$M$2:$M$86, "4", 'IT Risk Assessment Sheet'!$N$2:$N$86, "2") -> 0 | E4: =COUNTIFS('IT Risk Assessment Sheet'!$M$2:$M$86, "4", 'IT Risk Assessment Sheet'!$N$2:$N$86, "3") -> 2 | F4: =COUNTIFS('IT Risk Assessment Sheet'!$M$2:$M$86, "4", 'IT Risk Assessment Sheet'!$N$2:$N$86, "4") -> 4 | G4: =COUNTIFS('IT Risk Assessment Sheet'!$M$2:$M$86, "4", 'IT Risk Assessment Sheet'!$N$2:$N$86, "5") -> 1 | L4: 4 | M4: =COUNTIFS('IT Risk Assessment Sheet'!$R$2:$R$86, "4", 'IT Risk Assessment Sheet'!$S$2:$S$86, "1") -> 0 | N4: =COUNTIFS('IT Risk Assessment Sheet'!$R$2:$R$86, "4", 'IT Risk Assessment Sheet'!$S$2:$S$86, "2") -> 0 | O4: =COUNTIFS('IT Risk Assessment Sheet'!$R$2:$R$86, "4", 'IT Risk Assessment Sheet'!$S$2:$S$86, "3") -> 0 | P4: =COUNTIFS('IT Risk Assessment Sheet'!$R$2:$R$86, "5", 'IT Risk Assessment Sheet'!$S$2:$S$86, "4") -> 0 | Q4: =COUNTIFS('IT Risk Assessment Sheet'!$R$2:$R$86, "5", 'IT Risk Assessment Sheet'!$S$2:$S$86, "5") -> 0 | T4: Not Acceptable
B5: 3 | C5: =COUNTIFS('IT Risk Assessment Sheet'!$M$2:$M$86, "3", 'IT Risk Assessment Sheet'!$N$2:$N$86, "1") -> 1 | D5: =COUNTIFS('IT Risk Assessment Sheet'!$M$2:$M$86, "3", 'IT Risk Assessment Sheet'!$N$2:$N$86, "2") -> 12 | E5: =COUNTIFS('IT Risk Assessment Sheet'!$M$2:$M$86, "3", 'IT Risk Assessment Sheet'!$N$2:$N$86, "3") -> 28 | F5: =COUNTIFS('IT Risk Assessment Sheet'!$M$2:$M$86, "3", 'IT Risk Assessment Sheet'!$N$2:$N$86, "4") -> 26 | G5: =COUNTIFS('IT Risk Assessment Sheet'!$M$2:$M$86, "3", 'IT Risk Assessment Sheet'!$N$2:$N$86, "5") -> 0 | L5: 3 | M5: =COUNTIFS('IT Risk Assessment Sheet'!$R$2:$R$86, "3", 'IT Risk Assessment Sheet'!$S$2:$S$86, "1") -> 1 | N5: =COUNTIFS('IT Risk Assessment Sheet'!$R$2:$R$86, "3", 'IT Risk Assessment Sheet'!$S$2:$S$86, "2") -> 0 | O5: =COUNTIFS('IT Risk Assessment Sheet'!$R$2:$R$86, "3", 'IT Risk Assessment Sheet'!$S$2:$S$86, "3") -> 2 | P5: =COUNTIFS('IT Risk Assessment Sheet'!$R$2:$R$86, "3", 'IT Risk Assessment Sheet'!$S$2:$S$86, "4") -> 0 | Q5: =COUNTIFS('IT Risk Assessment Sheet'!$R$2:$R$86, "3", 'IT Risk Assessment Sheet'!$S$2:$S$86, "5") -> 0 | T5: Acceptable with further improvements
B6: 2 | C6: =COUNTIFS('IT Risk Assessment Sheet'!$M$2:$M$86, "2", 'IT Risk Assessment Sheet'!$N$2:$N$86, "1") -> 0 | D6: =COUNTIFS('IT Risk Assessment Sheet'!$M$2:$M$86, "2", 'IT Risk Assessment Sheet'!$N$2:$N$86, "2") -> 5 | E6: =COUNTIFS('IT Risk Assessment Sheet'!$M$2:$M$86, "2", 'IT Risk Assessment Sheet'!$N$2:$N$86, "3") -> 6 | F6: =COUNTIFS('IT Risk Assessment Sheet'!$M$2:$M$86, "2", 'IT Risk Assessment Sheet'!$N$2:$N$86, "4") -> 0 | G6: =COUNTIFS('IT Risk Assessment Sheet'!$M$2:$M$86, "2", 'IT Risk Assessment Sheet'!$N$2:$N$86, "5") -> 0 | L6: 2 | M6: =COUNTIFS('IT Risk Assessment Sheet'!$R$2:$R$86, "2", 'IT Risk Assessment Sheet'!$S$2:$S$86, "1") -> 11 | N6: =COUNTIFS('IT Risk Assessment Sheet'!$R$2:$R$86, "2", 'IT Risk Assessment Sheet'!$S$2:$S$86, "2") -> 51 | O6: =COUNTIFS('IT Risk Assessment Sheet'!$R$2:$R$86, "2", 'IT Risk Assessment Sheet'!$S$2:$S$86, "3") -> 14 | P6: =COUNTIFS('IT Risk Assessment Sheet'!$R$2:$R$86, "2", 'IT Risk Assessment Sheet'!$S$2:$S$86, "4") -> 0 | Q6: =COUNTIFS('IT Risk Assessment Sheet'!$R$2:$R$86, "2", 'IT Risk Assessment Sheet'!$S$2:$S$86, "5") -> 0 | T6: Acceptable Risk
B7: 1 | C7: =COUNTIFS('IT Risk Assessment Sheet'!$M$2:$M$86, "1", 'IT Risk Assessment Sheet'!$N$2:$N$86, "1") -> 0 | D7: =COUNTIFS('IT Risk Assessment Sheet'!$M$2:$M$86, "1", 'IT Risk Assessment Sheet'!$N$2:$N$86, "2") -> 0 | E7: =COUNTIFS('IT Risk Assessment Sheet'!$M$2:$M$86, "1", 'IT Risk Assessment Sheet'!$N$2:$N$86, "3") -> 0 | F7: =COUNTIFS('IT Risk Assessment Sheet'!$M$2:$M$86, "1", 'IT Risk Assessment Sheet'!$N$2:$N$86, "4") -> 0 | G7: =COUNTIFS('IT Risk Assessment Sheet'!$M$2:$M$86, "1", 'IT Risk Assessment Sheet'!$N$2:$N$86, "5") -> 0 | L7: 1 | M7: =COUNTIFS('IT Risk Assessment Sheet'!$R$2:$R$86, "1", 'IT Risk Assessment Sheet'!$S$2:$S$86, "1") -> 3 | N7: =COUNTIFS('IT Risk Assessment Sheet'!$R$2:$R$86, "1", 'IT Risk Assessment Sheet'!$S$2:$S$86, "2") -> 3 | O7: =COUNTIFS('IT Risk Assessment Sheet'!$R$2:$R$86, "1", 'IT Risk Assessment Sheet'!$S$2:$S$86, "3") -> 0 | P7: =COUNTIFS('IT Risk Assessment Sheet'!$R$2:$R$86, "1", 'IT Risk Assessment Sheet'!$S$2:$S$86, "4") -> 0 | Q7: =COUNTIFS('IT Risk Assessment Sheet'!$R$2:$R$86, "1", 'IT Risk Assessment Sheet'!$S$2:$S$86, "5") -> 0
C8: 1 | D8: 2 | E8: 3 | F8: 4 | G8: 5 | M8: 1 | N8: 2 | O8: 3 | P8: 4 | Q8: 5
C9: Severity/Impact | M9: Severity/Impact

Sheet IT Risk Assessment Sheet
A1: S.No | B1: Assets/Process | C1: Category | D1: Owner | E1: Custodian | F1: Location | G1: C | H1: I | I1: A | J1: CIA Score | K1: Threat | L1: Vulnerability | M1: Probability | N1: Impact | O1: Risk Score | P1: Existing Controls | Q1: Controls From 27001:2022 | R1: Probability | S1: Impact | T1: Residual Risk Score | U1: Recommended Action | V1: Management Response
A2: 1 | B2: IT Asset Management (Desktop, Laptops, Portable Data Storage Devices, Smartphones) | C2: Process | D2: IT Dept | E2: Individual | F2: Mobile | G2: 2 | H2: 2 | I2: 2 | J2: =G2*H2*I2 -> 8 | K2: Malicious Code,Malware, Ransomware | L2: No Antivirus, No patch management, No firewall, Outdated/End of life operating system, Lack of employee awareness | M2: 3 | N2: 3 | O2: =J2*M2*N2 -> 72 | P2: Crowdstrike EDR (Antivirus), Palo Alto NGFW with IDS & IPS, Fortigate Network Firewall, Zscaler web firewall & Zero Trust Network Architecture, Automatic patch updation through Microsoft Intune, Latest Windows OS version, Employee Awareness through Knowbe4 Security Training & Awareness platform, Halcyon anti ransomware tool | Q2: A.8.7 | R2: 2 | S2: 2 | T2: =J2*R2*S2 -> 32 | V2: Risk Accepted by Management
K3: Unauthorized Access | L3: Weak Access control, Weak Password Policy, No Session Timeout configured, No Accont Lockout configured, MFA not enabled, Login from unknown locations not restricted & monitored, Lack of employee awareness | M3: 3 | N3: 3 | O3: =J2*M3*N3 -> 72 | P3: Strong Password Policy, Multi Factor Authentication enabled & mandatory, Conditional Access Policy enabled on Office 365, Strong Access Controls, Session Timeout Configured, Account Lockout Configured, 24X7 Event Monitoring by SOC, Employee Awareness through Knowbe4 Security Training & Awareness platform, Darktrace IDM | Q3: A.5.15 A.5.18 A.8.1 A.8.3 A.8.5 A.8.16 | R3: 2 | S3: 2 | T3: =J2*R2*S2 -> 32 | V3: Risk Accepted by Management
K4: Hardware Failure | L4: Inadequate AMC, Aging H/W | M4: 3 | N4: 2 | O4: =J2*M4*N4 -> 48 | P4: H/W Warranty | Q4: A.7.13 | R4: 3 | S4: 1 | T4: =J2*R4*S4 -> 24 | V4: Risk Accepted by Management
K5: Data Loss | L5: No Antivirus, No backup mechanism, No patch management,No clear desk & clear screen policy | M5: 3 | N5: 3 | O5: =J2*M5*N5 -> 72 | P5: Data stored on cloud, Data stored in redundant locations, Recovery of Deleted Data, Azure Data Loss Prevention, Azure Information Protection, Archival & Retention Policies,Altaro Office 365 Backup, Hard Disk Encryption with Bitlocker, Intune Wipe, Clear Screen & Clear Desk policy, Employee Awareness through Knowbe4 Security Training & Awareness platform, Darktrace DLP, Bitraser Data Sanitization | Q5: A.7.7 A.8.10 A.8.12 | R5: 2 | S5: 2 | T5: =J2*R5*S5 -> 32 | V5: Risk Accepted by Management
K6: Data leakage | L6: No Data Sanitization, Lack of awareness, Malicious acts | M6: 3 | N6: 3 | O6: =J2*M6*N6 -> 72 | P6: 3rd Party Data Data Sanitization tool, Employee Discipline Procedure (HR) ,System Audit logs, NDA, Employee Awareness through Knowbe4 Security Training & Awareness platform | Q6: A.6.6 A.7.14 A.8.10 A.8.12 | R6: 2 | S6: 2 | T6: =J2*R6*S6 -> 32
K7: Loss of asset | L7: Inadequate Physical Security Controls, Inadequate Security procedures by employee, lack of awareness, negligence, No inventory of assets, Assets not labelled, Assets not returned by employee upon seperation, No insurance | M7: 2 | N7: 3 | O7: =J2*M7*N7 -> 48 | P7: Employee Awareness through Knowbe4 Security Training & Awareness platform, Employee Acknowldgement on IT Asset terms & conditions in helpdesk portal, Access Control System, Physical Security Controls, CCTV, Gatepass, Device Insurance, All IT assets labelled, IT Asset List maintained, Hard Disk Encryption with Bitlocker, Intune Wipe, Final Clearance Form signed by IT only upon return of assigned IT assets | Q7: A.5.9 A.5.10 A.5.11 A.7.3 A.7.9 | R7: 2 | S7: 1 | T7: =J2*R7*S7 -> 16 | V7: Risk Accepted by Management
A8: 2 | B8: IT Asset Management (Other IT Assets - Printers, Copy Machines) | C8: Process | D8: IT Dept | E8: Individual | F8: Fixed | G8: 1 | H8: 1 | I8: 1 | J8: =G8*H8*I8 -> 1 | K8: Hardware Failure | L8: Inadequate AMC, Aging H/W | M8: 3 | N8: 2 | O8: =J8*M8*N8 -> 6 | P8: H/W AMC & Warranty, Secure printing from any machine | Q8: A.7.13 | R8: 2 | S8: 1 | T8: =J8*R8*S8 -> 2 | V8: Risk Accepted by Management
K9: Loss of asset | L9: Inadequate Physical Security Controls, No inventory of assets, Assets not labelled, Assets not returned by employee upon seperation | M9: 3 | N9: 2 | O9: =J8*M9*N9 -> 6 | P9: Physical Security Controls, CCTV, Gatepass, All IT assets labelled, IT Asset List maintained, Final Clearance Form signed by IT only upon return of assigned IT assets | Q9: A.5.9 A.5.10 A.5.11 A.7.3 A.7.8 A.7.9 | R9: 1 | S9: 1 | T9: =J8*R9*S9 -> 1
K10: Data Loss | L10: Unauthorized Access | M10: 3 | N10: 2 | O10: =J8*M10*N10 -> 6 | P10: Printing secured with PIN/Windows Login & Password/Access Card | Q10: A.5.15 A.8.5 | R10: 2 | S10: 1 | T10: =J8*R10*S10 -> 2 | V10: Risk Accepted by Management
A11: 3 | B11: Endpoint Security | C11: Process | D11: IT Dept | E11: Individual | F11: Mobile | G11: 3 | H11: 3 | I11: 3 | J11: =G11*H11*I11 -> 27 | K11: Malicious Code,Malware, Ransomware | L11: No Antivirus, No patch management, No firewall, Outdated/End of life operating system, Lack of employee awareness | M11: 4 | N11: 4 | O11: =J11*M11*N11 -> 432 | P11: Crowdstrike EDR (Antivirus), Palo Alto NGFW with IDS & IPS, Fortigate Network Firewall, Zscaler web firewall & Zero Trust Network Architecture, Automatic patch updation through Microsoft Intune, Latest Windows OS version, Employee Awareness through Knowbe4 Security Training & Awareness platform, Halcyon anti ransomware tool | Q11: A.8.7 | R11: 3 | S11: 3 | T11: =J11*R11*S11 -> 243
K12: Unauthorized Access | L12: Weak Access control, Weak Password Policy, No Session Timeout configured, No Accont Lockout configured, MFA not enabled, Login from unknown locations not restricted & monitored, Lack of employee awareness | M12: 4 | N12: 3 | O12: =J11*M12*N12 -> 324 | P12: Strong Password Policy, Multi Factor Authentication enabled & mandatory, Conditional Access Policy enabled on Office 365, Strong Access Controls, Session Timeout Configured, Account Lockout Configured, 24X7 Event Monitoring by SOC, Employee Awareness through Knowbe4 Security Training & Awareness platform, Darktrace IDM | Q12: A.5.15 A.5.18 A.8.1 A.8.3 A.8.5 A.8.16 | R12: 2 | S12: 3 | T12: =J11*R12*S12 -> 162
K13: Data Loss | L13: No Antivirus, No backup mechanism, No patch management,No clear desk & clear screen policy | M13: 3 | N13: 3 | O13: =J11*M13*N13 -> 243 | P13: Data stored on cloud, Data stored in redundant locations, Recovery of Deleted Data, Azure Data Loss Prevention, Azure Information Protection, Archival & Retention Policies,Altaro Office 365 Backup, Hard Disk Encryption with Bitlocker, Intune Wipe, Clear Screen & Clear Desk policy, Employee Awareness through Knowbe4 Security Training & Awareness platform, Darktrace DLP, Bitraser Data Sanitization | Q13: A.7.7 A.8.10 A.8.12 | R13: 2 | S13: 3 | T13: =J11*R13*S13 -> 162
K14: Data leakage | L14: No Data Sanitization, Lack of awareness, Malicious acts | M14: 3 | N14: 3 | O14: =J11*M14*N14 -> 243 | P14: Intune Wipe, 3rd Party Data Data Sanitization tool, Employee Discipline Procedure (HR) ,System Audit logs, NDA, Employee Awareness through Knowbe4 Security Training & Awareness platform | Q14: A.6.6 A.7.14 A.8.10 A.8.12 | R14: 2 | S14: 2 | T14: =J11*R14*S14 -> 108
A15: 4 | B15: Physical Access Control (Access Control Devices, CCTV) | C15: Process | D15: IT Dept/Security | E15: IT Dept/Security | F15: Fixed | G15: 1 | H15: 1 | I15: 2 | J15: =G15*H15*I15 -> 2 | K15: Device Failure | L15: Inadequate AMC, Aging H/W | M15: 2 | N15: 2 | O15: =J15*M15*N15 -> 8 | P15: H/W AMC | Q15: A.7.13 | R15: 1 | S15: 1 | T15: =J15*R15*S15 -> 2 | V15: Risk Accepted by Management
K16: Unauthorized Access | L16: Equipment Tampering, Data loss | M16: 2 | N16: 2 | O16: =J15*M16*N16 -> 8 | P16: Access Control Devices, Centralized 24X7 CCTV Monitoring, Data Backup, Isolated Network, High Availability of Storage | Q16: A.7.3 A.7.4 | R16: 1 | S16: 2 | T16: =J15*R16*S16 -> 4 | V16: Risk Accepted by Management
A17: 5 | B17: Network Infrastructure Management (Routers, Access Switches, Core Switches, Wifi Routers, Firewall) | C17: Process | D17: IT Dept | E17: IT Dept | F17: Fixed | G17: 2 | H17: 2 | I17: 3 | J17: =G17*H17*I17 -> 12 | K17: Unauthorized Access | L17: Weak Access control | M17: 2 | N17: 3 | O17: =J17*M17*N17 -> 72 | P17: Strong Password Policy, Secure Network racks, Network segregation through VLAN's, Network Firewall | Q17: A.5.15 A.7.8 A.8.3 A.8.5 A.8.20 A.8.21 A.8.22 | R17: 2 | S17: 2 | T17: =J17*R17*S17 -> 48 | V17: Risk Accepted by Management
K18: Loss of asset | L18: Weak physical access control | M18: 2 | N18: 2 | O18: =J17*M18*N18 -> 48 | P18: Secure network racks, Access Control Devices, Centralized 24X7 CCTV Monitoring | Q18: A.7.3 A.7.4 A.7.8 A.8.20 | R18: 1 | S18: 2 | T18: =J17*R18*S18 -> 24 | V18: Risk Accepted by Management
K19: Hardware Failure, Old Network | L19: Inadequate AMC, Aging H/W | M19: 3 | N19: 4 | O19: =J17*M19*N19 -> 144 | P19: H/W AMC, Redundant Hardware | Q19: A.7.13 | R19: 2 | S19: 2 | T19: =J17*R19*S19 -> 48
K20: Unapproved Changes/configurations | L20: Malfunctioning, failure, service disruption | M20: 3 | N20: 4 | O20: =J17*M20*N20 -> 144 | P20: Change Management procedure, Roles & Responsibility Matrix, Changes done using Sectona PAM login, Recorded Sessions | Q20: A.5.3 A.8.9 A.8.32 | R20: 2 | S20: 2 | T20: =J17*R20*S20 -> 48
K21: Malicious Code,Malware, Ransomware, other network attacks (virus, botnet, DDOS, APT, MITM, Spoofing, Sniffing etc.) | L21: No network segregation, No firewall, Outdated/End of life firmware, Encryption not enabled, No network traffic/ log monitoring & review, No periodic VAPT | M21: 3 | N21: 3 | O21: =J17*M21*N21 -> 108 | P21: Network segregation through VLAN's, Secure VPN Tunnels, Palo Alto NGFW with IDS & IPS, Fortigate Network Firewall, Firmware upgrade, All network devices encrypted, Network Traffic routed through Zscaler ZTNA, 24X7 log monitoring by STC SOC, Quarterly VAPT conducted, Integration with NCSC SIEM, Darktrace NDR | Q21: A.8.7 A.8.8 A.8.16 A.8.20 A.8.21 A.8.22 A.8.24 | R21: 2 | S21: 2 | T21: =J17*R21*S21 -> 48 | V21: Risk Accepted by Management
A22: 6 | B22: Network Infrastructure Management (IP Telephony) | C22: Process | D22: IT Dept | E22: Individual | F22: Fixed | G22: 1 | H22: 1 | I22: 2 | J22: =G22*H22*I22 -> 2 | K22: Unauthorized Access | L22: Weak Access Controls | M22: 2 | N22: 2 | O22: =J22*M22*N22 -> 8 | P22: Dedicated MPLS Link, Username & password, Separate Voice VLAN, Server maintained by Service Provider | Q22: A.8.3 A.8.5 A.8.20 A.8.21 A.8.22 | R22: 1 | S22: 1 | T22: =J22*R22*S22 -> 2
K23: Hardware Failure | L23: No vendor support, service disruption | M23: 3 | N23: 1 | O23: =J22*M23*N23 -> 6 | P23: Warranty & Support Contract with vendor, Avaya Workspace application on smartphones, Microsoft Teams | Q23: A.7.13 A.8.14 | R23: 2 | S23: 1 | T23: =J22*R23*S23 -> 4
A24: 7 | B24: Network Cabling Management (Fiber & Other Network Cables) | C24: Process | D24: IT Dept | E24: IT Dept | F24: Fixed | G24: 1 | H24: 1 | I24: 3 | J24: =G24*H24*I24 -> 3 | K24: Cable Failure, Cable Taping | L24: Aging, catastrophic, Pest Attack, Civil work incidents | M24: 2 | N24: 3 | O24: =J24*M24*N24 -> 18 | P24: Cabling drawings, notification before Civil work, Pest control, Redundant arrangements, Wireless connectivity, Company Smartphone with internet facility | Q24: A.7.12 A.8.14 | R24: 2 | S24: 1 | T24: =J24*R24*S24 -> 6 | V24: Risk Accepted by Management
K25: Cable Cut | L25: No fiber cable redundancy, No Wireless connection backup | M25: 2 | N25: 3 | O25: =J24*M25*N25 -> 18 | P25: Fiber Cable Redundancy, Wireless Devices, company smartphones with internet | Q25: A.7.12 A.8.14 | R25: 2 | S25: 1 | T25: =J24*R25*S25 -> 6
A26: 8 | B26: Internet Access Management | C26: Process | D26: IT Dept | E26: Individual | F26: Fixed | G26: 1 | H26: 2 | I26: 3 | J26: =G26*H26*I26 -> 6 | K26: Malicious Code,Malware, Ransomware | L26: No Antivirus, No firewall, No Web Filtering, File download from internet not restricted, Lack of employee awareness | M26: 3 | N26: 3 | O26: =J26*M26*N26 -> 54 | P26: Crowdstrike EDR (Antivirus), Palo Alto NGFW with IDS & IPS, Fortigate Network Firewall, Web Filtering policies via Zscaler web firewall & Zero Trust Network Architecture, Employee Awareness through Knowbe4 Security Training & Awareness platform | Q26: A.8.7 A.8.16 | R26: 2 | S26: 2 | T26: =J26*R26*S26 -> 24
K27: Unauthorized Access | L27: Weak Access control, Weak Password Policy, No Session Timeout configured, No Accont Lockout configured, MFA not enabled, Internet Access open for all users, Lack of employee awareness | M27: 3 | N27: 3 | O27: =J26*M27*N27 -> 54 | P27: Strong Password Policy, Multi Factor Authentication enabled & mandatory, Strong Access Controls, Session Timeout Configured, Account Lockout Configured, 24X7 Event Monitoring by SOC, Internet Access Request procedure through Helpdesk, Employee Awareness through Knowbe4 Security Training & Awareness platform | Q27: A.5.15 A.5.18 A.8.3 A.8.5 A.8.16 | R27: 2 | S27: 3 | T27: =J26*R27*S27 -> 36
A28: 9 | B28: Data Backup Management (tape, Storage & Cloud based backup) | C28: Process | D28: IT Dept | E28: IT Dept | F28: IT Dept | G28: 3 | H28: 3 | I28: 2 | J28: =G28*H28*I28 -> 18 | K28: Backup Storage Device H/F Failure, Misconfiguration | L28: Inadequate AMC, Aging H/W | M28: 3 | N28: 2 | O28: =J28*M28*N28 -> 108 | P28: H/W AMC, Backup to storage and tapes,Office 365 backup on cloud via Altaro | Q28: A.7.13 A.8.13 | R28: 2 | S28: 1 | T28: =J28*R28*S28 -> 36 | V28: Risk Accepted by Management
K29: Unapproved Changes/configurations | L29: Malfunctioning, failure, service disruption | M29: 3 | N29: 4 | O29: =J28*M29*N29 -> 216 | P29: Change Management procedure, Roles & Responsibility Matrix | Q29: A.5.3 A.8.9 A.8.32 | R29: 2 | S29: 2 | T29: =J28*R29*S29 -> 72
K30: Tape Failure | L30: Poor Storage, No Restoration testing | M30: 3 | N30: 3 | O30: =J28*M30*N30 -> 162 | P30: Backup tapes stored in Clean and Safe ienvironment in external location, Quarterly restoration testing of backup tapes conducted | Q30: A.7.10 A.7.13 | R30: 2 | S30: 2 | T30: =J28*R30*S30 -> 72
K31: Backup Tapes Lost in Transit, Tapes handed over to unauthorized personnel | L31: Data Loss, Data Leakage, No inventory | M31: 3 | N31: 3 | O31: =J28*M31*N31 -> 162 | P31: Hand delivery of backup tapes by authorized ASRY IT personnel, use of the tape backup deposit/return form | Q31: A.5.9 A.5.14 A.7.10 A.7.13 | R31: 2 | S31: 2 | T31: =J28*R31*S31 -> 72
K32: Data Loss/Corruption | L32: No Backup, No backup log monitoring & review, No restoration testing, deleted files, database corruption | M32: 3 | N32: 2 | O32: =J28*M32*N32 -> 108 | P32: Daily, Weekly, Monthly and Yearly Backup to storage and tapes, Office 365 backup on cloud via Altaro, Daily backup log monitoring & review, Quarterly restoration testing of backup tapes conducted, Data stored on cloud, Data stored in redundant locations, Recovery of Deleted Data, Archival & Retention Policies, Contract & NDA, Vendor Support | Q32: A.5.23 A.8.13 A.8.15 A.8.16 | R32: 2 | S32: 2 | T32: =J28*R32*S32 -> 72 | V32: Risk Accepted by Management
A33: 10 | B33: Configuration Management | C33: Process | D33: IT Dept | E33: IT Dept | F33: Mobile | G33: 3 | H33: 3 | I33: 3 | J33: =G33*H33*I33 -> 27 | K33: System Failure, Service Disruption | L33: Bugs, Incorrect configuration, No Version Control, Lack of Technical Expertise, No Configuration Backup | M33: 3 | N33: 4 | O33: =J33*M33*N33 -> 324 | P33: Vendor Support, AMC, Backup to storage and tapes | Q33: A.8.9 | R33: 2 | S33: 2 | T33: =J33*R33*S33 -> 108 | V33: Risk Accepted by Management
K34: Unapproved Configurations | L34: Lack of defined change management policy & procedures | M34: 3 | N34: 4 | O34: =J33*M34*N34 -> 324 | P34: Defined configuration management policy & procedures,defined role & responsibility matrix for configuration changes, Changes done through Sectona login, Recorded Sessions | Q34: A.5.3 A.8.9 A.8.32 | R34: 2 | S34: 2 | T34: =J33*R34*S34 -> 108 | V34: Risk Accepted by Management
A35: 11 | B35: Change Management | C35: Process | D35: IT Dept | E35: IT Dept | F35: IT Dept | G35: 2 | H35: 2 | I35: 2 | J35: =G35*H35*I35 -> 8 | K35: Unapproved Changes | L35: Lack of defined change management policy & procedures | M35: 3 | N35: 3 | O35: =J35*M35*N35 -> 72 | P35: Defined change management policy & procedures,defined role & responsibility matrix for change | Q35: A.5.3 A.8.32 | R35: 2 | S35: 2 | T35: =J35*R35*S35 -> 32
K36: Unauthorized Access | L36: Weak Access control, Weak Password Policy, No Session Timeout configured, Privileged Access rights not properly assigned, No Log Monitoring & Access Review | M36: 3 | N36: 3 | O36: =J35*M36*N36 -> 72 | P36: Strong Password Policy, Multi Factor Authentication enabled & mandatory, Strong Access Controls, Session Timeout Configured, Account Lockout Configured, Privileged access given based on approval as per defined roles & responsibility matrix, Periocid log monitoring & Access Review | Q36: A.5.3 A.5.15 A.5.18 A.8.1 A.8.3 A.8.5 A.8.2 A.8.4 A.8.16 | R36: 2 | S36: 2 | T36: =J35*R36*S36 -> 32
K37: Data Loss/Corruption | L37: No Testing, No Backup, Development, Test & Production environments not separated | M37: 3 | N37: 2 | O37: =J35*M37*N37 -> 48 | P37: Change Management Procedure via Helpdesk, Rollback plan, Test Case sheet used for UAT, Backup to storage and tapes, Separate Development, Test and Production environments, Changes moved to Production upon successful testing | Q37: A.8.19 A.8.31 A.8.32 A.8.33 | R37: 2 | S37: 2 | T37: =J35*R37*S37 -> 32
A38: 12 | B38: Capacity Planning | C38: Process | D38: IT Dept | E38: IT Dept | F38: IT Dept | G38: 1 | H38: 1 | I38: 2 | J38: =G38*H38*I38 -> 2 | K38: System Failure, Service Disruption | L38: Lack of capacity utilization monitoring | M38: 3 | N38: 4 | O38: =J38*M38*N38 -> 24 | P38: Yearly Resource Forecasting, Scalable Cloud based Infrastructure, 24X7 Event Monitoring by SOC | Q38: A.8.6 | R38: 2 | S38: 2 | T38: =J38*R38*S38 -> 8 | V38: Risk Accepted by Management
A39: 13 | B39: Supplier/Vendor Management | C39: Process | D39: IT Dept | E39: IT Dept/Supply Chain | F39: Mobile | G39: 2 | H39: 2 | I39: 2 | J39: =G39*H39*I39 -> 8 | K39: Single source of support | L39: Non Availability | M39: 3 | N39: 3 | O39: =J39*M39*N39 -> 72 | P39: Identification of alternate support vendors | Q39: A.5.22 | R39: 2 | S39: 2 | T39: =J39*R39*S39 -> 32 | V39: Risk Accepted by Management
K40: Data Leakage | L40: No NDA, Data in vendor custody | M40: 3 | N40: 2 | O40: =J39*M40*N40 -> 48 | P40: NDA with vendors, All data is owned by ASRY, Maintenance activties done wth prior approval of ASRY. Supply Chain Dept. maintains a database of all IT vendors. | Q40: A.5.19 A.5.20 A.5.21 | R40: 2 | S40: 2 | T40: =J39*R40*S40 -> 32
...

Sheet IT Risk Assessment Process
A1: IT Risk Assessment Process
A3: Risk Definition | C3: Define Risk
A5: ABC (Assessment of Business Criticality) | C5: Risk ABC | E5: Evaluate Risk Level
A7: Risk Assessment | E7: Full Risk Assessment
A9: Security Standards | G9: Apply Security Standards | I9: Define Controls | K9: Benchmark
A11: Risk Register | M11: Set next Review Date | O11: Load Risk Register

Sheet Threat Catalogue
B1: ASRY IT Threat Catalogue
B2: External attack
C3: Distributing computer viruses (including worms)
C4: Distributing SPAM
C5: Introducing malicious code
C6: Introducing Trojan horses
C7: Undertaking malicious probes or scans
C8: Carrying out denial of service attacks
C9: Spoofing user identities
C10: Social engineering
C11: Spoofing web sites
C12: Hacking into systems
C13: Cracking passwords
C14: Defacing web sites
... C17: Eavesdropping
B18: Human Error
C19: Mistakes made by IT/network staff
C20: User mistakes
B21: Internal misuse / abuse
C22: Downloading or sending of inappropriate content
C23: Installing unauthorised software
C24: Changing or adding software without authorisation
C25: Disclosing business information
C26: Gaining unauthorised access to systems or networks
C27: Disclosing authentication information
C28: Changing system privileges without authorisation
C29: Misusing systems to commit fraud
C30: Misusing systems to cause disruption
C31: Modifying or inserting transactions, files or databases without authorisation
B32: Malfunctions
C33: Malfunction of computer/network equipment
C34: Malfunction of business application software acquired from a third party
C35: Malfunction of application software developed in-house
C36: Malfunction of system software
B37: Service interruption
C38: Damage to, or loss of, communications links/services
C39: Loss of power
C40: System overload (eg due to excessive volume of traffic)
C41: Damage to or loss of ancillary equipment (eg air conditioning or a heating/cooling plant)
C42: Damage to, or loss of, computer facilities
...

Sheet Applicaiton Specific Risk
B4: Application Specific Risk Prompts | C4: Data Masking | D4: Dummy data will be used for development and testing or not applicable. | E4: Masked production data will be used for development and testing. | F4: Production data will be used for development and testing.
B5: ID | C5: Risk Element ….. | D5: Low Risk Prompt | E5: Medium Risk Prompt | F5: High Risk Prompt | G5: Evaluation Result | H5: Include in Risk Register | I5: Comments
A6: Access Controls | B6: AC.1 | C6: Is there an effective segregation of duties to prevent inputters authorizing transactions and vice versa? | D6: Formal segregated activities exist for all users which would require collusion of two or more people in order to defraud. | E6: Formal segregated activities exist for most users which would require collusion of two or more people in order to defraud, exceptions could be IT support staff etc. | F6: No formal segregation of duties exist. | G6: na | H6: =IF(G6="H","Yes",IF(G6="M","Yes","No")) -> No
B7: AC.2 | C7: Are access control procedures in place and user access reviewed regularly? | D7: Procedures are in place for issuing and approving application access and user access control reports have been reviewed for accuracy and completeness within the last 6 months. | E7: Procedures are in place for issuing and approving application access and user access control reports have been reviewed for accuracy and completeness within the last 12 months. | F7: Procedures are in place for issuing and approving application access and user access control reports have not been reviewed for the last 12 months. | G7: na | H7: =IF(G7="H","Yes",IF(G7="M","Yes","No")) -> No
B8: AC.3 | C8: Are procedures defined for the timely deletion/disabling of application specific user accounts (e.g., hires, terminations, changes in responsibility etc)? | D8: Monthly housekeeping routines are run to ensure the timely deletion/disabling of application specific user accounts. | E8: Quarterly housekeeping routines are run to ensure the timely deletion/disabling of application specific user accounts. | F8: Housekeeping routines are run on an ad-hoc basis. | G8: na | H8: =IF(G8="H","Yes",IF(G8="M","Yes","No")) -> No
B9: AC.4 | C9: Are access controls in place to ensure users are restricted to Read, Write, Execute, Delete based on individual business application requirements? | D9: Role based access controls are in place and documented for all users. | E9: Role based access controls are in place for all users. | F9: Access controls are applied at the individual user level. | G9: na | H9: =IF(G9="H","Yes",IF(G9="M","Yes","No")) -> No
A10: Database Controls | B10: DBC.1 | C10: Has the database been fully documented including, structure, schema, relationships etc? | D10: There is a comprehensive set of documentation which has been reviewed, and updated where necessary within the past 12 months. | E10: Documentation exists for the database but it has not been reviewed or updated within the past 12 months. | F10: Little or no documentation exists for the database. | G10: na | H10: =IF(G10="H","Yes",IF(G10="M","Yes","No")) -> No
B11: DBC.2 | C11: Are database integrity checks run periodically? | D11: Database integrity checks are run on a regular basis and back-up copies of the database are retained from one check to the next. | E11: Database integrity checks have not been run within the past 12 months. | F11: Database integrity checks have not been run within the past 24 months. | G11: na | H11: =IF(G11="H","Yes",IF(G11="M","Yes","No")) -> No
B12: DBC.3 | C12: Has the database been through the process of normalization? | D12: The database has been through third form normalization. | E12: The database has been through second form normalization. | F12: The database has been through first form normalization. | G12: na | H12: =IF(G12="H","Yes",IF(G12="M","Yes","No")) -> No
B13: DBC.4 | C13: Are there Data validation rules in place within the database? | D13: Data validation rules are in place for all values entered into the database including direct user inputs and data entered automatically via batch jobs etc. | E13: Data validation rules are in place for most values entered into the database including direct user inputs and data entered automatically via batch jobs etc. | F13: Data validation rules are in place for some values entered into the database including direct user inputs and data entered automatically via batch jobs etc. | G13: na | H13: =IF(G13="H","Yes",IF(G13="M","Yes","No")) -> No
B14: DBC.5 | C14: Has the Referential Integrity of the database been assessed? | D14: Referential Integrity rules have been set up for all tables in the database and these have been validated within the last 12 months. | E14: Referential Integrity rules have been set up for all tables in the database. | F14: Referential Integrity rules have been set up for some tables in the database. | G14: na | H14: =IF(G14="H","Yes",IF(G14="M","Yes","No")) -> No
A15: Input Controls | B15: IC.1 | C15: Are input screens designed to prevent the omission of data and the acceptance of invalid data? | D15: Input screens are designed only to accept complete and valid entries. | E15: Input screens are designed to accept valid data, but will accept incomplete entries. | F15: Input screens will accept incomplete entries and invalid data. | G15: na | H15: =IF(G15="H","Yes",IF(G15="M","Yes","No")) -> No
A16: Output Controls | B16: OC.1 | C16: Is there a documented output requirements definition? | D16: There is a detailed documented output requirements definition which is based on user requirements and it takes into account the different types of recipients, usage, details required, frequency, method of generation etc. | E16: There is a documented output requirements definition. | F16: There is no documented output requirements document. | G16: na | H16: =IF(G16="H","Yes",IF(G16="M","Yes","No")) -> No
B17: OC.2 | C17: Is the data classification clearly indicated on all printed and on screen data output? | D17: All output is clearly marked with a data classification in line with Zurich's classification schema. | E17: All output is clearly marked with a data classification, but it is not in line with the Zurich standard classification schema. | F17: Output is not marked with a data classification. | G17: na | H17: =IF(G17="H","Yes",IF(G17="M","Yes","No")) -> No
A18: Application Development | B18: AD.1 | C18: Are there separate facilities (logical or physical) for Development, Test and Production software? | D18: Separate dedicated environments are in place for all Development, Test and Production software for the application. | E18: Separate shared (with other applications) environments are in place for all Development, Test and Production software for the application. | F18: There are no separate environments for application Development, Test and Production software for the application. | G18: na | H18: =IF(G18="H","Yes",IF(G18="M","Yes","No")) -> No
B19: AD.2 | C19: Are compilers, editors and system utilities set up as to not be accessible from the Production systems? | D19: Compilers, editors and system utilities are not accessible from the Production systems. | E19: Compilers, editors and system utilities are accessible from the Production systems for authorized users. | F19: Compilers, editors and system utilities are accessible from the Production systems by all users. | G19: na | H19: =IF(G19="H","Yes",IF(G19="M","Yes","No")) -> No
B20: AD.3 | C20: Are logon procedures and user names different between Development, Test and Production environments? | D20: There are unique users names for development, Test and Production environments. | E20: There are unique users names for the Production environments. | F20: There are common user names for Development, Test and Production environments. | G20: na | H20: =IF(G20="H","Yes",IF(G20="M","Yes","No")) -> No
A21: Monitoring System & Use | B21: MS.1 | C21: Is application event logging enabled and are the logs stored for review? | D21: Comprehensive audit logs of event logging containing user names, dates & times for logon, etc are enabled and the logs are stored for a minimum of 12 months. | E21: Comprehensive audit logs of event logging containing user names, dates & times for logon, etc are enabled and the logs are stored for a minimum of 6 months. | F21: Audit logs of event logging containing user names, dates & times for logon, etc are enabled but are not stored for a minimum of 6 months. | G21: na | H21: =IF(G21="H","Yes",IF(G21="M","Yes","No")) -> No
B22: MS.2 | C22: Are there procedures for the review of application event logs? | D22: Documented procedures exist and reviews are undertaken every 3 months. | E22: Documented procedures exist and reviews are undertaken every 6 months. | F22: Reviews are undertaken on an ad-hoc basis. | G22: na | H22: =IF(G22="H","Yes",IF(G22="M","Yes","No")) -> No

Sheet Security Specific Risk
B4: Security Specific Risk Prompts | C4: Data Masking | D4: Dummy data will be used for development and testing or not applicable. | E4: Masked production data will be used for development and testing. | F4: Production data will be used for development and testing.
B5: ID | C5: Risk Element ….. | D5: Low Risk Prompt | E5: Medium Risk Prompt | F5: High Risk Prompt | G5: Evaluation Result | H5: Include in Risk Register | I5: Comments
A6: Policies & Standards | B6: PS.1 | C6: Is the application compliant to all G-ITR policies (The "Blue Book") | D6: Compliance to the Blue Book has been verified by an independent external assessment or by G-ITR during the past six months | E6: Compliance to the Blue Book has been verified by an independent external assessment or by G-ITR more than six months ago. | F6: Compliance to the Blue Book has never been verified or there are known deviations to the Blue Book. | G6: na | H6: =IF(G6="","",IF(G6="L","N",(IF(G6="NA","N","Yes")))) -> N
B7: PS.2 | C7: Have information security responsibilities for the service been clearly defined and assigned? | D7: Information security responsibilities for the service have been formally assigned and documented. | E7: Information security responsibilities for the service have been agreed but not documented | F7: Information security responsibilities have not been agreed | G7: na | H7: =IF(G7="","",IF(G7="L","N",(IF(G7="NA","N","Yes")))) -> N
B8: PS.3 | C8: Has the G-ITR IT Security Architecture been implemented in the area under review? | D8: The Service is fully aligned to the G-ITR Security Architecture and Patterns | E8: Most of the Service is fully aligned to the G-ITR Security Architecture and Patterns | F8: Some elements of the Service are aligned to the G-ITR Security Architecture and Patterns | G8: na | H8: =IF(G8="","",IF(G8="L","N",(IF(G8="NA","N","Yes")))) -> N
A9: User Access Management | B9: UAM.1 | C9: Are there additional controls in place for users with highly privileged accounts? | D9: Additional controls are in place for all privileged user accounts including the use of separate user names. | E9: Additional controls are in place for all privileged user accounts. | F9: There are no additional controls in place for users with highly privileged accounts. | G9: na | H9: =IF(G9="","",IF(G9="L","N",(IF(G9="NA","N","Yes")))) -> N
B10: UAM.2 | C10: Are there controls in place to ensure that users do not share user names. Controls could be Technical, Logical or Procedural. | D10: There are controls in place to prevent users sharing credentials and these have been validated in the past six months. | E10: There are controls in place to prevent users sharing credentials and these have not been validated in the past six months. | F10: There are no controls in place to prevent users sharing credentials | G10: na | H10: =IF(G10="","",IF(G10="L","N",(IF(G10="NA","N","Yes")))) -> N
B11: UAM.3 | C11: Is two-factor authentication used for remote access users, including third-parties? | D11: All remote access uses two-factor authentication. | E11: Two-factor authentication is only used in some cases for remote access. | F11: Two-factor authentication is not used for remote access. | G11: na | H11: =IF(G11="","",IF(G11="L","N",(IF(G11="NA","N","Yes")))) -> N
A12: Network security | B12: NS.1 | C12: Is the network supported by documentation, including standards, procedures, configurations etc? | D12: There is a comprehensive set of supporting documentation that has been reviewed in the past 12 months. | E12: Supporting documentation exists for the key components of the network and it is subject to periodic review. | F12: There is little or no supporting documentation for the network. | G12: na | H12: =IF(G12="","",IF(G12="L","N",(IF(G12="NA","N","Yes")))) -> N
B13: NS.2 | C13: Is there intrusion detection systems employed on the application supporting infrastructure. | D13: Intrusion detection systems are employed and alerts are continuously monitored. | E13: Intrusion detection systems are employed but alerts are not continuously monitored. | F13: There is no intrusion detection in place | G13: na | H13: =IF(G13="","",IF(G13="L","N",(IF(G13="NA","N","Yes")))) -> N
B14: NS.3 | C14: Have appropriate controls been put in place to limit single-points-of-failure within the application supporting infrastructure? | D14: The application supporting infrastructure is fully resilient with no single-points-of-failure | E14: Most key aspects of the application supporting infrastructure are fully resilient | F14: The application supporting infrastructure has several single-points-of-failure | G14: na | H14: =IF(G14="","",IF(G14="L","N",(IF(G14="NA","N","Yes")))) -> N
B15: NS.4 | C15: Has the application supporting infrastructure been subject to a penetration test? | D15: Regular penetration testing takes place and a test has been completed within the past 6 months. | E15: Regular penetration testing takes place and a test has been completed within the past 12 months. | F15: A penetration test has not be undertaken for over 12 months. | G15: na | H15: =IF(G15="","",IF(G15="L","N",(IF(G15="NA","N","Yes")))) -> N
A16: Application Security | B16: AS.1 | C16: Are application security controls documented? | D16: There is a comprehensive set of security documentation which has been reviewed, and updated where necessary within the past 12 months. | E16: Security documentation exists but it has not been reviewed or updated within the past 12 months. | F16: Little or no security documentation exists for the application. | G16: na | H16: =IF(G16="","",IF(G16="L","N",(IF(G16="NA","N","Yes")))) -> N
B17: AS.2 | C17: Has the application been subject to an application vulnerability scan? | D17: The application has had an application security scan within the past 6 months and action plans put in place to mitigate any identified weaknesses. | E17: The application has had an application security scan within the past 12 months and all identified weaknesses have been mitigated. | F17: The application has not had an application security scan within the past 12 months. | G17: na | H17: =IF(G17="","",IF(G17="L","N",(IF(G17="NA","N","Yes")))) -> N
B18: AS.3 | C18: Is the transfer of sensitive information protected from unauthorized disclosure by approved methods e.g. encrypting the information, digital signatures etc. | D18: Sensitive information is protected by encryption and/or digital signatures as approved by G-ITR | E18: Sensitive information is protected by encryption and/or digital signatures but the mechanisms have not been approved by G-ITR | F18: Sensitive information is not protected by encryption and/or digital signatures | G18: na | H18: =IF(G18="","",IF(G18="L","N",(IF(G18="NA","N","Yes")))) -> N
B19: AS.4 | C19: Are application access logs reviewed to detect unusual user activity patterns or misuse? | D19: Application access logs are regularly reviewed and any action taken recorded. | E19: Application access logs are reviewed on an ad-hoc basis | F19: Application access logs are not reviewed | G19: na | H19: =IF(G19="","",IF(G19="L","N",(IF(G19="NA","N","Yes")))) -> N
A20: Workstation & Server Security | B20: WSS.1 | C20: Are standard configurations used for all workstations and servers (Systems) that support the application? | D20: Standard, documented, configurations are used on all systems. | E20: Standard, documented, configurations are used on most systems. | F20: Standard configurations are used on some systems. | G20: na | H20: =IF(G20="","",IF(G20="L","N",(IF(G20="NA","N","Yes")))) -> N | I20: =IF(J20=1,"Not Applicable as compliant to Blue Book","")
B21: WSS.2 | C21: Has a patch management framework been implemented for all Systems? | D21: Process and procedures exist to ensure the patching of all systems in line with G-ITR requirements. | E21: Process and procedures exist to ensure the patching of most systems in line with G-ITR requirements. | F21: Patching of systems is ad-hoc. | G21: na | H21: =IF(G21="","",IF(G21="L","N",(IF(G21="NA","N","Yes")))) -> N
B22: WSS.3 | C22: Are systems protected from virus, malicious code, Trojans etc? | D22: Virus and malicious code protection software is in place and automatically updated on a daily basis. | E22: Virus and malicious code protection software is in place and automatically updated on a weekly basis. | F22: Virus and malicious code protection software is only in place on parts of the system. | G22: na | H22: =IF(G22="","",IF(G22="L","N",(IF(G22="NA","N","Yes")))) -> N
B23: WSS.4 | C23: Are workstation and server event logs reviewed to detect unusual user activity patterns or misuse? | D23: Event logs are regularly reviewed and any action taken recorded. | E23: Event logs are reviewed on an ad-hoc basis | F23: Event logs are not reviewed | G23: na | H23: =IF(G23="","",IF(G23="L","N",(IF(G23="NA","N","Yes")))) -> N
A24: Third-party Access | B24: TPA.1 | C24: Where third party access arrangements exist are they reviewed periodically to assess compliance to policy? | D24: Compliance to policy checks are undertaken on a regular basis. | E24: Compliance to policy checks are undertaken on an ad-hoc basis | F24: No compliance to policy checks are undertaken. | G24: na | H24: =IF(G24="","",IF(G24="L","N",(IF(G24="NA","N","Yes")))) -> N
B25: TPA.2 | C25: Have security reviews taken place at third-party sites where Zurich data is processed? | D25: A full security review at all third-party premises processing Zurich data has taken place. | E25: A full security review at some third-party premises processing Zurich data has taken place. | F25: No security reviews of third-party premises have taken place. | G25: na | H25: =IF(G25="","",IF(G25="L","N",(IF(G25="NA","N","Yes")))) -> N
H26: =IF(G26="","",IF(G26="L","N",(IF(G26="NA","N","Yes"))))
H27: =IF(G27="","",IF(G27="L","N",(IF(G27="NA","N","Yes"))))
H28: =IF(G28="","",IF(G28="L","N",(IF(G28="NA","N","Yes"))))
H29: =IF(G29="","",IF(G29="L","N",(IF(G29="NA","N","Yes"))))
H30: =IF(G30="","",IF(G30="L","N",(IF(G30="NA","N","Yes"))))
H31: =IF(G31="","",IF(G31="L","N",(IF(G31="NA","N","Yes"))))
H32: =IF(G32="","",IF(G32="L","N",(IF(G32="NA","N","Yes"))))
H33: =IF(G33="","",IF(G33="L","N",(IF(G33="NA","N","Yes"))))
H34: =IF(G34="","",IF(G34="L","N",(IF(G34="NA","N","Yes"))))
H35: =IF(G35="","",IF(G35="L","N",(IF(G35="NA","N","Yes"))))
H36: =IF(G36="","",IF(G36="L","N",(IF(G36="NA","N","Yes"))))
H37: =IF(G37="","",IF(G37="L","N",(IF(G37="NA","N","Yes"))))
... H103: =IF(G103="","",IF(G103="L","N",(IF(G103="NA","N","Yes"))))

Sheet Service Op & Support Risk
B4: Service Operations & Support Risk Prompts
B5: ID | C5: Risk Element …………….. | D5: Low Risk Prompt | E5: Medium Risk Prompt | F5: High Risk Prompt | G5: Evaluation Result | H5: Include in Risk Register | I5: Comments
A6: Change Management | B6: ChM.1 | C6: Is there a formal change management process in operation? | D6: There is a formal change process in place and there have been no incidence of unauthorized changes within the past 12 months. | E6: There is a formal change management process in place but there have been incidence of unauthorized changes taking place within the last 12 months. | F6: There is a formal change management process in place but there have been incidence of unauthorized changes taking place within the last 6 months. | G6: na | H6: =IF(G6="H","Yes",IF(G6="M","Yes","No")) -> No
B7: ChM.2 | C7: Are proposed changes formally accepted by the service owner before being implemented? | D7: The service owner (or delegate) is one of the formal approvers for all changes relating to the service. | E7: The service owner (or delegate) is notified of all changes impacting the service but does not formally approve the changes. | F7: The service owner is not involved in the change process at all. | G7: na | H7: =IF(G7="H","Yes",IF(G7="M","Yes","No")) -> No
B8: ChM.3 | C8: Are changes rigorously tested and their impact assessed before they are implemented? | D8: All changes are tested and their impact assessed prior to the change being implemented. | E8: Some changes are not tested and impact assessments are not always completed. | F8: Changes are not tested and the impact is not assessed. | G8: na | H8: =IF(G8="H","Yes",IF(G8="M","Yes","No")) -> No
B9: ChM.4 | C9: Are 'rollback' procedures developed and tested as part of the change process? | D9: All changes have tested rollback procedures in place in the event of failure of the change. | E9: Rollback procedures are normally developed but it is not always possible to test rollback procedures. | F9: Rollback procedures are not normally developed or are only sporadically tested. | G9: na | H9: =IF(G9="H","Yes",IF(G9="M","Yes","No")) -> No
B10: ChM.5 | C10: Have there been any Severity 1 incidents to the service due to the unforeseen effects of a change? | D10: There have been no Severity 1 Incidents due to the unforeseen effects of change in the last 12 months. | E10: There have been Severity 1 incidents in the last 12 months due to the unforeseen effects of a change. | F10: There have been Severity 1 incidents in the last six months due to the unforeseen effects of a change. | G10: na | H10: =IF(G10="H","Yes",IF(G10="M","Yes","No")) -> No
A11: Problem Management | B11: PM.1 | C11: Is there a formal problem and incident management process in operation? | D11: There is a formal problem and incident management process in place which is followed for all incidents. | E11: There is a formal problem and incident management process in place which only covers Severity 1 incidents. | F11: There is no formal problem and incident management process in place. | G11: na | H11: =IF(G11="H","Yes",IF(G11="M","Yes","No")) -> No
B12: PM.2 | C12: Does the resolution of problems and incidents include an investigation and analysis of the root cause? | D12: Root cause analysis is documented for all problems and incidents. | E12: Root cause analysis is only completed for Severity 1 problems and incidents. | F12: A root cause analysis is only undertaken on an ad-hoc basis for problems and incidents. | G12: na | H12: =IF(G12="H","Yes",IF(G12="M","Yes","No")) -> No
B13: PM.3 | C13: Are risks identified and documented in a risk register as a result of problems and incidents? | D13: Risks are identified and documented in a risk register for all problems and incidents. | E13: Risks are identified and documented for all Severity 1 incidents. | F13: Risks are not formally identified or documented for problems and incidents. | G13: na | H13: =IF(G13="H","Yes",IF(G13="M","Yes","No")) -> No
B14: PM.4 | C14: Are identified mitigating actions for measures implemented to reduce the likelihood of problems and incidents reoccurring tracked? | D14: All mitigating actions are assigned a due date and owner and are formally tracked to completion. | E14: Mitigating actions for Severity 1 incidents are assigned a due date and owner and are formally tracked to completion. | F14: There is no formal process for tracking mitigating action to completion. | G14: na | H14: =IF(G14="H","Yes",IF(G14="M","Yes","No")) -> No
A15: Software Control and Distribution | B15: SCD.1 | C15: Are there technical controls in place to ensure that there is not a breach of software license compliance or infringements of copyright etc? | D15: Technical controls are in place to ensure that unlicensed software is not installed for all the Service's software. | E15: Technical controls are in place to ensure that unlicensed software is not installed for some of the Service's software. | F15: There are no technical controls in place to prevent breaches of software licensing. | G15: na | H15: =IF(G15="H","Yes",IF(G15="M","Yes","No")) -> No
B16: SCD.2 | C16: Does the software distribution method include formal change control processes? | D16: All software distribution for the Service is completed under formal change control processes. | E16: Only major software distribution for the Service is completed under formal change control processes, bug fixes, patching etc is done under business as usual. | F16: Software distribution is not under change control. | G16: na | H16: =IF(G16="H","Yes",IF(G16="M","Yes","No")) -> No
B17: SCD.3 | C17: Is there a reliable software version control system in place? | D17: Controls are in place to manage version control for all software and all platforms employed by the Service. | E17: Controls are in place to manage version control for some of the software and platforms employed by the Service. | F17: There are no controls in place to manage version control. | G17: na | H17: =IF(G17="H","Yes",IF(G17="M","Yes","No")) -> No
B18: SCD.4 | C18: Has the software code being subject to security testing and code reviews and vulnerability scanning? | D18: All code is subject to security testing and code reviews prior to being put into production. | E18: Major code changes are subject to security testing and code reviews prior to being put into production. | F18: Security testing and extensive code reviews do not take place. | G18: na | H18: =IF(G18="H","Yes",IF(G18="M","Yes","No")) -> No
